PS C:\Users\XRSpecial\gigapose-1> python refine.py test_dataset_name=tless run_id=$NAME_RUN
Traceback (most recent call last):
  File "C:\Users\XRSpecial\gigapose-1\refine.py", line 9, in <module>
    from src.custom_megapose.refiner_utils import find_init_pose_path
  File "C:\Users\XRSpecial\gigapose-1\src\custom_megapose\refiner_utils.py", line 12, in <module>
    from src.megapose.training.pose_models_cfg import create_model_pose
  File "C:\Users\XRSpecial\gigapose-1\src\megapose\training\pose_models_cfg.py", line 27, in <module>
    from src.megapose.models.pose_rigid import PosePredictor
  File "C:\Users\XRSpecial\gigapose-1\src\megapose\models\pose_rigid.py", line 36, in <module>
    from src.megapose.lib3d.cropping import deepim_crops_robust as deepim_crops_robust
  File "C:\Users\XRSpecial\gigapose-1\src\megapose\lib3d\cropping.py", line 23, in <module>
    from src.megapose.datasets.pose_dataset import PoseDataset
  File "C:\Users\XRSpecial\gigapose-1\src\megapose\datasets\pose_dataset.py", line 29, in <module>
    from src.megapose.config import LOCAL_DATA_DIR
  File "C:\Users\XRSpecial\gigapose-1\src\megapose\config.py", line 46, in <module>
    BLENDER_INSTALL_DIR = Path(os.environ["HOME"]) / BLENDER_VERSION
  File "C:\Users\XRSpecial\miniconda3\envs\gigapose\lib\os.py", line 679, in __getitem__
    raise KeyError(key) from None
KeyError: 'HOME'
PS C:\Users\XRSpecial\gigapose-1> 
