PS C:\Users\XRSpecial\gigapose-1> python test.py test_dataset_name=tless run_id=$NAME_RUN
[2024-08-15 13:45:10,757][__main__][INFO] - Initializing logger, callbacks and trainer
[2024-08-15 13:45:10,760][__main__][INFO] - Tensorboard logger initialized at ./gigaPose_datasets/results/large_/gigapose
Error executing job with overrides: ['test_dataset_name=tless', 'run_id=']
Traceback (most recent call last):
  File "C:\Users\XRSpecial\miniconda3\envs\gigapose\lib\site-packages\hydra\_internal\instantiate\_instantiate2.py", line 92, in _call_target
    return _target_(*args, **kwargs)
  File "C:\Users\XRSpecial\miniconda3\envs\gigapose\lib\site-packages\pytorch_lightning\utilities\argparse.py", line 70, in insert_env_defaults
    return fn(self, **kwargs)
  File "C:\Users\XRSpecial\miniconda3\envs\gigapose\lib\site-packages\pytorch_lightning\trainer\trainer.py", line 400, in __init__
    self._accelerator_connector = _AcceleratorConnector(
  File "C:\Users\XRSpecial\miniconda3\envs\gigapose\lib\site-packages\pytorch_lightning\trainer\connectors\accelerator_connector.py", line 143, in __init__
    self._accelerator_flag = self._choose_gpu_accelerator_backend()
  File "C:\Users\XRSpecial\miniconda3\envs\gigapose\lib\site-packages\pytorch_lightning\trainer\connectors\accelerator_connector.py", line 353, in _choose_gpu_accelerator_backend
    raise MisconfigurationException("No supported gpu backend found!")
lightning_fabric.utilities.exceptions.MisconfigurationException: No supported gpu backend found!

The above exception was the direct cause of the following exception:

Traceback (most recent call last):
  File "C:\Users\XRSpecial\gigapose-1\test.py", line 87, in <module>
    run_test()
  File "C:\Users\XRSpecial\miniconda3\envs\gigapose\lib\site-packages\hydra\main.py", line 94, in decorated_main
    _run_hydra(
  File "C:\Users\XRSpecial\miniconda3\envs\gigapose\lib\site-packages\hydra\_internal\utils.py", line 394, in _run_hydra
    _run_app(
  File "C:\Users\XRSpecial\miniconda3\envs\gigapose\lib\site-packages\hydra\_internal\utils.py", line 457, in _run_app
    run_and_report(
  File "C:\Users\XRSpecial\miniconda3\envs\gigapose\lib\site-packages\hydra\_internal\utils.py", line 223, in run_and_report
    raise ex
  File "C:\Users\XRSpecial\miniconda3\envs\gigapose\lib\site-packages\hydra\_internal\utils.py", line 220, in run_and_report
    return func()
  File "C:\Users\XRSpecial\miniconda3\envs\gigapose\lib\site-packages\hydra\_internal\utils.py", line 458, in <lambda>
    lambda: hydra.run(
  File "C:\Users\XRSpecial\miniconda3\envs\gigapose\lib\site-packages\hydra\_internal\hydra.py", line 132, in run
    _ = ret.return_value
  File "C:\Users\XRSpecial\miniconda3\envs\gigapose\lib\site-packages\hydra\core\utils.py", line 260, in return_value
    raise self._return_value
  File "C:\Users\XRSpecial\miniconda3\envs\gigapose\lib\site-packages\hydra\core\utils.py", line 186, in run_job
    ret.return_value = task_function(task_cfg)
  File "C:\Users\XRSpecial\gigapose-1\test.py", line 43, in run_test
    trainer = instantiate(cfg_trainer)
  File "C:\Users\XRSpecial\miniconda3\envs\gigapose\lib\site-packages\hydra\_internal\instantiate\_instantiate2.py", line 226, in instantiate
    return instantiate_node(
  File "C:\Users\XRSpecial\miniconda3\envs\gigapose\lib\site-packages\hydra\_internal\instantiate\_instantiate2.py", line 347, in instantiate_node
    return _call_target(_target_, partial, args, kwargs, full_key)
  File "C:\Users\XRSpecial\miniconda3\envs\gigapose\lib\site-packages\hydra\_internal\instantiate\_instantiate2.py", line 97, in _call_target
    raise InstantiationException(msg) from e
hydra.errors.InstantiationException: Error in call to target 'pytorch_lightning.trainer.trainer.Trainer':
MisconfigurationException('No 
