PS C:\Users\XRSpecial\gigapose-1> & C:/Users/XRSpecial/miniconda3/envs/gigapose/python.exe c:/Users/XRSpecial/gigapose-1/bop_toolkit/scripts/vis_est_poses.py
8/26|13:11:42: Processing: C:\Users\XRSpecial\gigapose-1\gigaPose_datasets\results\large_\refined_multiple_predictions\large-pbrreal-rgb-mmodel_tless-test_MultiHypothesis.csv
[w] Backend (<module 'glumpy.app.window.backends.backend_glfw' from 'C:\\Users\\XRSpecial\\miniconda3\\envs\\gigapose\\lib\\site-packages\\glumpy\\app\\window\\backends\\backend_glfw.py'>) not availableWARNING:glumpy:[w] Backend (<module 'glumpy.app.window.backends.backend_glfw' from 'C:\\Users\\XRSpecial\\miniconda3\\envs\\gigapose\\lib\\site-packages\\glumpy\\app\\window\\backends\\backend_glfw.py'>) not available
[w] Backend (<module 'glumpy.app.window.backends.backend_glfw_deprecated' from 'C:\\Users\\XRSpecial\\miniconda3\\envs\\gigapose\\lib\\site-packages\\glumpy\\app\\window\\backends\\backend_glfw_deprecated.py'>) not available
WARNING:glumpy:[w] Backend (<module 'glumpy.app.window.backends.backend_glfw_deprecated' from 'C:\\Users\\XRSpecial\\miniconda3\\envs\\gigapose\\lib\\site-packages\\glumpy\\app\\window\\backends\\backend_glfw_deprecated.py'>) not available
[w] Backend (<module 'glumpy.app.window.backends.backend_glfw' from 'C:\\Users\\XRSpecial\\miniconda3\\envs\\gigapose\\lib\\site-packages\\glumpy\\app\\window\\backends\\backend_glfw.py'>) not availableWARNING:glumpy:[w] Backend (<module 'glumpy.app.window.backends.backend_glfw' from 'C:\\Users\\XRSpecial\\miniconda3\\envs\\gigapose\\lib\\site-packages\\glumpy\\app\\window\\backends\\backend_glfw.py'>) not available
[w] Backend (<module 'glumpy.app.window.backends.backend_glfw_imgui' from 'C:\\Users\\XRSpecial\\miniconda3\\envs\\gigapose\\lib\\site-packages\\glumpy\\app\\window\\backends\\backend_glfw_imgui.py'>) not available
WARNING:glumpy:[w] Backend (<module 'glumpy.app.window.backends.backend_glfw_imgui' from 'C:\\Users\\XRSpecial\\miniconda3\\envs\\gigapose\\lib\\site-packages\\glumpy\\app\\window\\backends\\backend_glfw_imgui.py'>) not available
8/26|13:11:43: Loading 3D model of object 1...
Traceback (most recent call last):
  File "c:\Users\XRSpecial\gigapose-1\bop_toolkit\scripts\vis_est_poses.py", line 106, in <module>
    ren.add_object(obj_id, model_path, surf_color=model_color)
  File "C:\Users\XRSpecial\miniconda3\envs\gigapose\lib\site-packages\bop_toolkit_lib\renderer_py.py", line 396, in add_object
    list(zip(model["pts"], model["normals"], colors, texture_uv)),
KeyError: 'normals'
PS C:\Users\XRSpecial\gigapose-1>

